2024-09-27T00:09:17 we are stuck hard, help!
2024-09-27T00:42:52 we are stuck hard, help! , sleep 3600*24
2024-09-27T00:42:52 we are stuck hard, help! , sleep 3600*24
2024-09-27T00:42:52 '  File "quest.py", line 4208, in <module>\n    current_quest_area = getQuestArea(poe_bot.game_data.area_raw_name)\n'
2024-09-27T00:42:52 '  File "quest.py", line 4200, in getQuestArea\n    area_object = area_class()\n'
2024-09-27T00:42:52 '  File "quest.py", line 1401, in __init__\n    self.enterAfterResurrect()\n'
2024-09-27T00:42:52 '  File "quest.py", line 1384, in enterAfterResurrect\n    self.enterBossroomIfNeeded()\n'
2024-09-27T00:42:52 '  File "quest.py", line 1217, in enterBossroomIfNeeded\n    bossroom_encounter.leaveBossroom()\n'
2024-09-27T00:42:52 '  File "C:\\poe_bot\\1_host\\utils\\encounters.py", line 244, in leaveBossroom\n    res = mover.goToPoint(\n'
2024-09-27T00:42:52 '  File "C:\\poe_bot\\1_host\\utils\\mover.py", line 389, in goToPoint\n    poe_bot.raiseLongSleepException(\'we are stuck hard, help!\')\n'
2024-09-27T00:42:52 '  File "C:\\poe_bot\\1_host\\utils\\gamehelper.py", line 354, in raiseLongSleepException\n    raiseLongSleepException(text)\n'
2024-09-27T00:42:52 '  File "C:\\poe_bot\\1_host\\utils\\utils.py", line 108, in raiseLongSleepException\n    raise Exception(f\'{text} , sleep 3600*24\')\n'
2024-09-27T00:44:15 #resurrectAtCheckpoint call 1727369055.9611883
2024-09-27T00:45:34 1_5_town current area isn't supported
2024-09-27T00:45:34 1_5_town current area isn't supported
2024-09-27T00:45:34 '  File "quest.py", line 4208, in <module>\n    current_quest_area = getQuestArea(poe_bot.game_data.area_raw_name)\n'
2024-09-27T00:45:34 '  File "quest.py", line 4198, in getQuestArea\n    raise Exception(f"{area_raw_name} current area isn\'t supported")\n'
2024-09-27T07:56:11 couldnt check the key
2024-09-27T07:56:11 couldnt check the key
2024-09-27T07:56:11 '  File "quest.py", line 737, in <module>\n    poe_bot = PoeBot(unique_id=UNIQUE_ID, remote_ip = REMOTE_IP)\n'
2024-09-27T07:56:11 '  File "C:\\poe_bot\\1_host\\utils\\gamehelper.py", line 101, in __init__\n    self.checkIfReady()\n'
2024-09-27T07:56:11 '  File "C:\\poe_bot\\1_host\\utils\\gamehelper.py", line 142, in checkIfReady\n    raise Exception(\'couldnt check the key\')\n'
2024-09-27T07:56:30 #resurrectAtCheckpoint call 1727394990.518566
2024-09-27T08:00:41 #resurrectAtCheckpoint call 1727395241.4457705
2024-09-27T08:01:03 #resurrectAtCheckpoint call 1727395263.436746
2024-09-27T08:03:47 #resurrectAtCheckpoint call 1727395427.6754444
2024-09-27T08:09:05 #resurrectAtCheckpoint call 1727395745.4341261
2024-09-27T08:10:05 #resurrectAtCheckpoint call 1727395805.8176937
2024-09-27T08:17:53 #resurrectAtCheckpoint call 1727396273.0454772
2024-09-27T08:18:04 #resurrectAtCheckpoint call 1727396284.8887792
2024-09-27T08:23:42 #resurrectAtCheckpoint call 1727396622.1901877
2024-09-27T08:30:33 #resurrectAtCheckpoint call 1727397033.9964235
2024-09-27T08:32:25 1_5_6 current area isn't supported
2024-09-27T08:32:25 1_5_6 current area isn't supported
2024-09-27T08:32:25 '  File "quest.py", line 4208, in <module>\n    current_quest_area = getQuestArea(poe_bot.game_data.area_raw_name)\n'
2024-09-27T08:32:25 '  File "quest.py", line 4198, in getQuestArea\n    raise Exception(f"{area_raw_name} current area isn\'t supported")\n'
2024-09-27T08:32:27 1_5_6 current area isn't supported
2024-09-27T08:32:27 1_5_6 current area isn't supported
2024-09-27T08:32:27 '  File "quest.py", line 4208, in <module>\n    current_quest_area = getQuestArea(poe_bot.game_data.area_raw_name)\n'
2024-09-27T08:32:27 '  File "quest.py", line 4198, in getQuestArea\n    raise Exception(f"{area_raw_name} current area isn\'t supported")\n'
2024-09-27T08:32:29 1_5_6 current area isn't supported
2024-09-27T08:32:29 1_5_6 current area isn't supported
2024-09-27T08:32:29 '  File "quest.py", line 4208, in <module>\n    current_quest_area = getQuestArea(poe_bot.game_data.area_raw_name)\n'
2024-09-27T08:32:29 '  File "quest.py", line 4198, in getQuestArea\n    raise Exception(f"{area_raw_name} current area isn\'t supported")\n'
2024-09-27T08:32:31 1_5_6 current area isn't supported
2024-09-27T08:32:31 1_5_6 current area isn't supported
2024-09-27T08:32:31 '  File "quest.py", line 4208, in <module>\n    current_quest_area = getQuestArea(poe_bot.game_data.area_raw_name)\n'
2024-09-27T08:32:31 '  File "quest.py", line 4198, in getQuestArea\n    raise Exception(f"{area_raw_name} current area isn\'t supported")\n'
2024-09-27T08:32:34 1_5_6 current area isn't supported
2024-09-27T08:32:34 1_5_6 current area isn't supported
2024-09-27T08:32:34 '  File "quest.py", line 4208, in <module>\n    current_quest_area = getQuestArea(poe_bot.game_data.area_raw_name)\n'
2024-09-27T08:32:34 '  File "quest.py", line 4198, in getQuestArea\n    raise Exception(f"{area_raw_name} current area isn\'t supported")\n'
2024-09-27T08:32:35 1_5_6 current area isn't supported
2024-09-27T08:32:35 1_5_6 current area isn't supported
2024-09-27T08:32:35 '  File "quest.py", line 4208, in <module>\n    current_quest_area = getQuestArea(poe_bot.game_data.area_raw_name)\n'
2024-09-27T08:32:35 '  File "quest.py", line 4198, in getQuestArea\n    raise Exception(f"{area_raw_name} current area isn\'t supported")\n'
2024-09-27T08:32:39 1_5_6 current area isn't supported
2024-09-27T08:32:39 1_5_6 current area isn't supported
2024-09-27T08:32:39 '  File "quest.py", line 4208, in <module>\n    current_quest_area = getQuestArea(poe_bot.game_data.area_raw_name)\n'
2024-09-27T08:32:39 '  File "quest.py", line 4198, in getQuestArea\n    raise Exception(f"{area_raw_name} current area isn\'t supported")\n'
2024-09-27T08:46:13 1_5_6 current area isn't supported
2024-09-27T08:46:13 1_5_6 current area isn't supported
2024-09-27T08:46:13 '  File "quest.py", line 4229, in <module>\n    current_quest_area = getQuestArea(poe_bot.game_data.area_raw_name)\n'
2024-09-27T08:46:13 '  File "quest.py", line 4219, in getQuestArea\n    raise Exception(f"{area_raw_name} current area isn\'t supported")\n'
2024-09-27T08:46:48 couldnt check the key
2024-09-27T08:46:48 couldnt check the key
2024-09-27T08:46:48 '  File "quest.py", line 737, in <module>\n    poe_bot = PoeBot(unique_id=UNIQUE_ID, remote_ip = REMOTE_IP)\n'
2024-09-27T08:46:48 '  File "C:\\poe_bot\\1_host\\utils\\gamehelper.py", line 101, in __init__\n    self.checkIfReady()\n'
2024-09-27T08:46:48 '  File "C:\\poe_bot\\1_host\\utils\\gamehelper.py", line 142, in checkIfReady\n    raise Exception(\'couldnt check the key\')\n'
2024-09-27T08:53:19 we are stuck hard, help!
2024-09-27T09:05:18 exceptions must derive from BaseException
2024-09-27T09:05:18 exceptions must derive from BaseException
2024-09-27T09:05:18 '  File "quest.py", line 4255, in <module>\n    current_quest_area.complete()\n'
2024-09-27T09:05:18 '  File "quest.py", line 1194, in complete\n    raise "completed"\n'
2024-09-27T11:52:15 #resurrectAtCheckpoint call 1727409135.181909
2024-09-27T11:52:42 #resurrectAtCheckpoint call 1727409162.0039167
2024-09-27T12:40:22 we are stuck hard, help!
2024-09-27T12:40:26 #resurrectAtCheckpoint call 1727412026.5246007
2024-09-27T13:46:48 #resurrectAtCheckpoint call 1727416008.9061043
2024-09-27T13:48:50 #resurrectAtCheckpoint call 1727416130.4252315
2024-09-27T13:49:06 Goal of (548, 4709) lies outside grid.
2024-09-27T13:49:06 Goal of (548, 4709) lies outside grid.
2024-09-27T13:49:06 '  File "quest.py", line 4280, in <module>\n    current_quest_area = getQuestArea(poe_bot.game_data.area_raw_name)\n'
2024-09-27T13:49:06 '  File "quest.py", line 4272, in getQuestArea\n    area_object = area_class()\n'
2024-09-27T13:49:06 '  File "quest.py", line 3479, in __init__\n    super().__init__()\n'
2024-09-27T13:49:06 '  File "quest.py", line 1402, in __init__\n    self.enterAfterResurrect()\n'
2024-09-27T13:49:06 '  File "quest.py", line 1385, in enterAfterResurrect\n    self.enterBossroomIfNeeded()\n'
2024-09-27T13:49:06 '  File "quest.py", line 1220, in enterBossroomIfNeeded\n    self.clearBossroom(bossroom_encounter)\n'
2024-09-27T13:49:06 '  File "quest.py", line 3497, in clearBossroom\n    bossroom_encounter.clearBossroom()\n'
2024-09-27T13:49:06 '  File "C:\\poe_bot\\1_host\\utils\\encounters.py", line 194, in clearBossroom\n    self.killBoss(entity=entity)\n'
2024-09-27T13:49:06 '  File "C:\\poe_bot\\1_host\\utils\\encounters.py", line 120, in killBoss\n    res = mover.goToPoint(\n'
2024-09-27T13:49:06 '  File "C:\\poe_bot\\1_host\\utils\\mover.py", line 308, in goToPoint\n    path = poe_bot.pather.generatePath((int(poe_bot.game_data.player.grid_pos.y), int(poe_bot.game_data.player.grid_pos.x)), (grid_pos_to_go_y, grid_pos_to_go_x) )\n'
2024-09-27T13:49:06 '  File "C:\\poe_bot\\1_host\\utils\\pathing.py", line 123, in generatePath\n    path = pyastar2d.astar_path(self.terrain_for_a_star, start, end, allow_diagonal=False)\n'
2024-09-27T13:49:06 '  File "C:\\Users\\1\\AppData\\Local\\Programs\\Python\\Python38\\lib\\site-packages\\pyastar2d\\astar_wrapper.py", line 63, in astar_path\n    raise ValueError(f"Goal of {goal} lies outside grid.")\n'
2024-09-27T13:50:00 #resurrectAtCheckpoint call 1727416200.3525038
2024-09-27T13:50:28 cannot find prisoners gate
2024-09-27T13:51:38 cannot find prisoners gate
2024-09-27T13:54:18 cannot find prisoners gate , sleep 3600*24
2024-09-27T13:54:18 cannot find prisoners gate , sleep 3600*24
2024-09-27T13:54:18 '  File "quest.py", line 4281, in <module>\n    current_quest_area = getQuestArea(poe_bot.game_data.area_raw_name)\n'
2024-09-27T13:54:18 '  File "quest.py", line 1099, in complete\n    res = poe_bot.mover.goToPoint(\n'
2024-09-27T13:54:18 '  File "C:\\poe_bot\\1_host\\utils\\mover.py", line 293, in goToPoint\n    custom_break_function_result = custom_break_function(self)\n'
2024-09-27T13:54:18 '  File "quest.py", line 1057, in exploreRoutine\n    self.clearBossroom(bossroom_encounter)\n'
2024-09-27T13:54:18 '  File "quest.py", line 3497, in clearBossroom\n    bossroom_encounter.clear_room_custom_break_function=lookForWardensChambers\n'
2024-09-27T13:54:18 '  File "C:\\poe_bot\\1_host\\utils\\encounters.py", line 204, in clearBossroom\n    res = mover.goToPoint(\n'
2024-09-27T13:54:18 '  File "C:\\poe_bot\\1_host\\utils\\mover.py", line 293, in goToPoint\n    custom_break_function_result = custom_break_function(self)\n'
2024-09-27T13:54:18 '  File "C:\\poe_bot\\1_host\\utils\\encounters.py", line 186, in custom_break_function_nested\n    res = self.clear_room_custom_break_function(self.poe_bot.mover)\n'
2024-09-27T13:54:18 '  File "quest.py", line 3492, in lookForWardensChambers\n    poe_bot.game_data.terrain.getCurrentlyPassableArea()\n'
2024-09-27T13:54:18 '  File "C:\\poe_bot\\1_host\\utils\\gamehelper.py", line 354, in raiseLongSleepException\n    raiseLongSleepException(text)\n'
2024-09-27T13:54:18 '  File "C:\\poe_bot\\1_host\\utils\\utils.py", line 108, in raiseLongSleepException\n    raise Exception(f\'{text} , sleep 3600*24\')\n'
2024-09-27T13:54:29 'NoneType' object has no attribute 'grid_position'
2024-09-27T13:54:29 'NoneType' object has no attribute 'grid_position'
2024-09-27T13:54:29 '  File "quest.py", line 4282, in <module>\n    current_quest_area.complete()\n'
2024-09-27T13:54:29 '  File "quest.py", line 1099, in complete\n    res = poe_bot.mover.goToPoint(\n'
2024-09-27T13:54:29 '  File "C:\\poe_bot\\1_host\\utils\\mover.py", line 293, in goToPoint\n    custom_break_function_result = custom_break_function(self)\n'
2024-09-27T13:54:29 '  File "quest.py", line 1057, in exploreRoutine\n    self.clearBossroom(bossroom_encounter)\n'
2024-09-27T13:54:29 '  File "quest.py", line 3498, in clearBossroom\n    bossroom_encounter.clearBossroom()\n'
2024-09-27T13:54:29 '  File "C:\\poe_bot\\1_host\\utils\\encounters.py", line 204, in clearBossroom\n    res = mover.goToPoint(\n'
2024-09-27T13:54:29 '  File "C:\\poe_bot\\1_host\\utils\\mover.py", line 293, in goToPoint\n    custom_break_function_result = custom_break_function(self)\n'
2024-09-27T13:54:29 '  File "C:\\poe_bot\\1_host\\utils\\encounters.py", line 186, in custom_break_function_nested\n    res = self.clear_room_custom_break_function(self.poe_bot.mover)\n'
2024-09-27T13:54:29 '  File "quest.py", line 3494, in lookForWardensChambers\n    poe_bot.mover.goToPoint((pos_x, pos_y), release_mouse_on_end=False, custom_break_function=lookForPrisonersTransition)\n'
2024-09-27T13:54:29 '  File "C:\\poe_bot\\1_host\\utils\\mover.py", line 293, in goToPoint\n    custom_break_function_result = custom_break_function(self)\n'
2024-09-27T13:54:29 '  File "quest.py", line 3488, in lookForPrisonersTransition\n    poe_bot.mover.goToEntitysPoint(prisoners_gate_transition)\n'
2024-09-27T13:54:29 '  File "C:\\poe_bot\\1_host\\utils\\mover.py", line 568, in goToEntitysPoint\n    entity_pos = [entity_to_go.grid_position.x, entity_to_go.grid_position.y]\n'
2024-09-27T13:55:09 'NoneType' object has no attribute 'grid_position'
2024-09-27T13:55:09 'NoneType' object has no attribute 'grid_position'
2024-09-27T13:55:09 '  File "quest.py", line 4282, in <module>\n    current_quest_area = getQuestArea(poe_bot.game_data.area_raw_name)\n'
2024-09-27T13:55:09 '  File "quest.py", line 1099, in complete\n    res = poe_bot.mover.goToPoint(\n'
2024-09-27T13:55:09 '  File "C:\\poe_bot\\1_host\\utils\\mover.py", line 293, in goToPoint\n    custom_break_function_result = custom_break_function(self)\n'
2024-09-27T13:55:09 '  File "quest.py", line 1057, in exploreRoutine\n    self.clearBossroom(bossroom_encounter)\n'
2024-09-27T13:55:09 '  File "quest.py", line 3498, in clearBossroom\n    bossroom_encounter.clear_room_custom_break_function=lookForWardensChambers\n'
2024-09-27T13:55:09 '  File "C:\\poe_bot\\1_host\\utils\\encounters.py", line 204, in clearBossroom\n    res = mover.goToPoint(\n'
2024-09-27T13:55:09 '  File "C:\\poe_bot\\1_host\\utils\\mover.py", line 456, in goToPoint\n    custom_break_function_result = custom_break_function(self)\n'
2024-09-27T13:55:09 '  File "C:\\poe_bot\\1_host\\utils\\encounters.py", line 186, in custom_break_function_nested\n    res = self.clear_room_custom_break_function(self.poe_bot.mover)\n'
2024-09-27T13:55:09 '  File "quest.py", line 3494, in lookForWardensChambers\n    pos_x, pos_y = poe_bot.game_data.terrain.getFurtherstPassablePoint()\n'
2024-09-27T13:55:09 '  File "C:\\poe_bot\\1_host\\utils\\mover.py", line 293, in goToPoint\n    custom_break_function_result = custom_break_function(self)\n'
2024-09-27T13:55:09 '  File "quest.py", line 3488, in lookForPrisonersTransition\n    if prisoners_gate_transition:\n'
2024-09-27T13:55:09 '  File "C:\\poe_bot\\1_host\\utils\\mover.py", line 568, in goToEntitysPoint\n    entity_pos = [entity_to_go.grid_position.x, entity_to_go.grid_position.y]\n'
2024-09-27T15:17:41 exceptions must derive from BaseException
2024-09-27T15:17:41 exceptions must derive from BaseException
2024-09-27T15:17:41 '  File "quest.py", line 4283, in <module>\n    current_quest_area.complete()\n'
2024-09-27T15:17:41 '  File "quest.py", line 1195, in complete\n    raise "completed"\n'
2024-09-27T15:27:48 #resurrectAtCheckpoint call 1727422068.666314
2024-09-27T16:26:34 name 'mover' is not defined
2024-09-27T16:26:34 name 'mover' is not defined
2024-09-27T16:26:34 '  File "quest.py", line 4331, in <module>\n    current_quest_area.complete()\n'
2024-09-27T16:26:34 '  File "quest.py", line 1100, in complete\n    res = poe_bot.mover.goToPoint(\n'
2024-09-27T16:26:34 '  File "C:\\poe_bot\\1_host\\utils\\mover.py", line 456, in goToPoint\n    custom_break_function_result = custom_break_function(self)\n'
2024-09-27T16:26:34 '  File "quest.py", line 1034, in exploreRoutine\n    extra_quest_result = self.extraQuestInLoc()\n'
2024-09-27T16:26:34 '  File "quest.py", line 3620, in extraQuestInLoc\n    mover.move(grid_pos_x = point[0], grid_pos_y = point[1])\n'
2024-09-27T16:27:26 'int' object is not iterable
2024-09-27T16:27:26 'int' object is not iterable
2024-09-27T16:27:26 '  File "quest.py", line 4331, in <module>\n    current_quest_area.complete()\n'
2024-09-27T16:27:26 '  File "quest.py", line 1100, in complete\n    res = poe_bot.mover.goToPoint(\n'
2024-09-27T16:27:26 '  File "C:\\poe_bot\\1_host\\utils\\mover.py", line 456, in goToPoint\n    custom_break_function_result = custom_break_function(self)\n'
2024-09-27T16:27:26 '  File "quest.py", line 1034, in exploreRoutine\n    extra_quest_result = self.extraQuestInLoc()\n'
2024-09-27T16:27:26 '  File "quest.py", line 3627, in extraQuestInLoc\n    print(f\'distance to fuel tank = {dist(beacon_payload.grid_position.x, beacon_payload.grid_position.y)}\')\n'
2024-09-27T16:55:20 #resurrectAtCheckpoint call 1727427320.291162
2024-09-27T16:55:29 #resurrectAtCheckpoint call 1727427329.3299494
2024-09-27T16:55:49 #resurrectAtCheckpoint call 1727427349.6249695
2024-09-27T16:56:14 #resurrectAtCheckpoint call 1727427374.1969292
2024-09-27T16:56:23 #resurrectAtCheckpoint call 1727427383.686154
2024-09-27T16:58:47 #resurrectAtCheckpoint call 1727427527.4176447
2024-09-27T18:05:35 exceptions must derive from BaseException
2024-09-27T18:05:35 exceptions must derive from BaseException
2024-09-27T18:05:35 '  File "quest.py", line 4346, in <module>\n    current_quest_area.complete()\n'
2024-09-27T18:05:35 '  File "quest.py", line 1196, in complete\n    raise "completed"\n'
2024-09-27T18:18:37 activator disappeared
2024-09-27T18:19:54 #resurrectAtCheckpoint call 1727432394.530986
2024-09-27T18:43:18 relogging
2024-09-27T19:26:49 #resurrectAtCheckpoint call 1727436409.0557244
2024-09-27T20:16:49 exceptions must derive from BaseException
2024-09-27T20:16:49 exceptions must derive from BaseException
2024-09-27T20:16:49 '  File "quest.py", line 4448, in <module>\n    current_quest_area.complete()\n'
2024-09-27T20:16:49 '  File "quest.py", line 1196, in complete\n    raise "completed"\n'
2024-09-27T20:16:54 #resurrectAtCheckpoint call 1727439414.2410197
2024-09-27T20:17:41 exceptions must derive from BaseException
2024-09-27T20:17:41 exceptions must derive from BaseException
2024-09-27T20:17:41 '  File "quest.py", line 4448, in <module>\n    current_quest_area.complete()\n'
2024-09-27T20:17:41 '  File "quest.py", line 1196, in complete\n    raise "completed"\n'
2024-09-27T20:25:05 #resurrectAtCheckpoint call 1727439905.0612853
2024-09-27T20:27:07 exceptions must derive from BaseException
2024-09-27T20:27:07 exceptions must derive from BaseException
2024-09-27T20:27:07 '  File "quest.py", line 4448, in <module>\n    current_quest_area.complete()\n'
2024-09-27T20:27:07 '  File "quest.py", line 1196, in complete\n    raise "completed"\n'
2024-09-27T20:50:15 #resurrectAtCheckpoint call 1727441415.0916767
2024-09-27T20:54:01 #resurrectAtCheckpoint call 1727441641.4629319
2024-09-27T21:38:45 2_8_2_2 current area isn't supported
2024-09-27T21:38:45 2_8_2_2 current area isn't supported
2024-09-27T21:38:45 '  File "quest.py", line 4447, in <module>\n    current_quest_area = getQuestArea(poe_bot.game_data.area_raw_name)\n'
2024-09-27T21:38:45 '  File "quest.py", line 4437, in getQuestArea\n    raise Exception(f"{area_raw_name} current area isn\'t supported")\n'
2024-09-27T22:19:19 we are stuck hard, help!
