2024-11-03T01:57:40 mousePress() takes from 1 to 5 positional arguments but 6 were given
2024-11-03T01:57:40 '  File "quest.py", line 4818, in <module>\n    current_quest_area.complete()\n'
2024-11-03T01:57:40 '  File "quest.py", line 1130, in complete\n    res = poe_bot.mover.goToPoint(\n'
2024-11-03T01:57:40 '  File "D:\\poe_bot\\1_host\\utils\\mover.py", line 522, in goToPoint\n    self.move(screen_pos_x=int(pos_to_click[0]), screen_pos_y=int(pos_to_click[1]))\n'
2024-11-03T01:57:40 '  File "D:\\poe_bot\\1_host\\utils\\mover.py", line 639, in move\n    bot_controls.mouse.press(pos_x,pos_y)\n'
2024-11-03T01:57:40 '  File "D:\\poe_bot\\1_host\\utils\\controller.py", line 274, in press\n    self.controller.mousePress(x,y,button,force,wait_till_executed)\n'
2024-11-03T01:58:39 couldnt check the key
2024-11-03T01:58:39 '  File "quest.py", line 775, in <module>\n    poe_bot = PoeBot(unique_id=UNIQUE_ID, remote_ip = REMOTE_IP, debug = notebook_dev)\n'
2024-11-03T01:58:39 '  File "D:\\poe_bot\\1_host\\utils\\gamehelper.py", line 94, in __init__\n    self.checkIfReady()\n'
2024-11-03T01:58:39 '  File "D:\\poe_bot\\1_host\\utils\\gamehelper.py", line 132, in checkIfReady\n    raise Exception(\'couldnt check the key\')\n'
2024-11-03T02:06:44 supposed to have the key
2024-11-03T02:22:39 supposed to have the key , sleep 3600*24
2024-11-03T02:22:39 '  File "quest.py", line 4818, in <module>\n    current_quest_area.complete()\n'
2024-11-03T02:22:39 '  File "quest.py", line 1130, in complete\n    res = poe_bot.mover.goToPoint(\n'
2024-11-03T02:22:39 '  File "D:\\poe_bot\\1_host\\utils\\mover.py", line 501, in goToPoint\n    custom_break_function_result = custom_break_function(self)\n'
2024-11-03T02:22:39 '  File "quest.py", line 1090, in exploreRoutine\n    self.clearBossroom(bossroom_encounter)\n'
2024-11-03T02:22:39 '  File "quest.py", line 1293, in clearBossroom\n    self.onBossroomCompleteFunction()\n'
2024-11-03T02:22:39 '  File "quest.py", line 3076, in onBossroomCompleteFunction\n    poe_bot.raiseLongSleepException(\'supposed to have the key\')\n'
2024-11-03T02:22:39 '  File "D:\\poe_bot\\1_host\\utils\\gamehelper.py", line 293, in raiseLongSleepException\n    raiseLongSleepException(text)\n'
2024-11-03T02:22:39 '  File "D:\\poe_bot\\1_host\\utils\\utils.py", line 43, in raiseLongSleepException\n    raise Exception(f\'{text} , sleep 3600*24\')\n'
2024-11-03T02:24:26 couldnt check the key
2024-11-03T02:24:26 '  File "quest.py", line 775, in <module>\n    poe_bot = PoeBot(unique_id=UNIQUE_ID, remote_ip = REMOTE_IP, debug = notebook_dev)\n'
2024-11-03T02:24:26 '  File "D:\\poe_bot\\1_host\\utils\\gamehelper.py", line 94, in __init__\n    self.checkIfReady()\n'
2024-11-03T02:24:26 '  File "D:\\poe_bot\\1_host\\utils\\gamehelper.py", line 132, in checkIfReady\n    raise Exception(\'couldnt check the key\')\n'
2024-11-03T02:30:09 exceptions must derive from BaseException
2024-11-03T02:30:09 '  File "quest.py", line 4818, in <module>\n    current_quest_area.complete()\n'
2024-11-03T02:30:09 '  File "quest.py", line 1225, in complete\n    raise "completed"\n'
2024-11-03T02:34:28 list index out of range
2024-11-03T02:34:28 '  File "quest.py", line 785, in <module>\n    poe_bot.game_data.terrain.getCurrentlyPassableArea()\n'
2024-11-03T02:34:28 '  File "D:\\poe_bot\\1_host\\utils\\gamehelper.py", line 462, in getCurrentlyPassableArea\n    nearest_passable_player_point = list(list(zip(nearest_passable_player_points[0], nearest_passable_player_points[1]))[0])\n'
2024-11-03T02:37:17 #resurrectAtCheckpoint call 1730572637.0867753
2024-11-03T02:38:15 #resurrectAtCheckpoint call 1730572695.4946678
2024-11-03T02:38:34 #resurrectAtCheckpoint call 1730572714.4448726
2024-11-03T02:47:31 1_4_town current area isn't supported
2024-11-03T02:47:31 '  File "quest.py", line 4817, in <module>\n    current_quest_area = getQuestArea(poe_bot.game_data.area_raw_name)\n'
2024-11-03T02:47:31 '  File "quest.py", line 4807, in getQuestArea\n    raise Exception(f"{area_raw_name} current area isn\'t supported")\n'
2024-11-03T02:47:33 1_4_town current area isn't supported
2024-11-03T02:47:33 '  File "quest.py", line 4817, in <module>\n    current_quest_area = getQuestArea(poe_bot.game_data.area_raw_name)\n'
2024-11-03T02:47:33 '  File "quest.py", line 4807, in getQuestArea\n    raise Exception(f"{area_raw_name} current area isn\'t supported")\n'
2024-11-03T13:15:57 exceptions must derive from BaseException
2024-11-03T13:15:57 '  File "quest.py", line 4818, in <module>\n    current_quest_area.complete()\n'
2024-11-03T13:15:57 '  File "quest.py", line 1225, in complete\n    raise "completed"\n'
2024-11-03T13:17:04 1_4_town current area isn't supported
2024-11-03T13:17:04 '  File "quest.py", line 4817, in <module>\n    current_quest_area = getQuestArea(poe_bot.game_data.area_raw_name)\n'
2024-11-03T13:17:04 '  File "quest.py", line 4807, in getQuestArea\n    raise Exception(f"{area_raw_name} current area isn\'t supported")\n'
2024-11-03T13:17:06 1_4_town current area isn't supported
2024-11-03T13:17:06 '  File "quest.py", line 4817, in <module>\n    current_quest_area = getQuestArea(poe_bot.game_data.area_raw_name)\n'
2024-11-03T13:17:06 '  File "quest.py", line 4807, in getQuestArea\n    raise Exception(f"{area_raw_name} current area isn\'t supported")\n'
2024-11-03T13:17:07 1_4_town current area isn't supported
2024-11-03T13:17:07 '  File "quest.py", line 4817, in <module>\n    current_quest_area = getQuestArea(poe_bot.game_data.area_raw_name)\n'
2024-11-03T13:17:07 '  File "quest.py", line 4807, in getQuestArea\n    raise Exception(f"{area_raw_name} current area isn\'t supported")\n'
2024-11-03T13:17:09 1_4_town current area isn't supported
2024-11-03T13:17:09 '  File "quest.py", line 4817, in <module>\n    current_quest_area = getQuestArea(poe_bot.game_data.area_raw_name)\n'
2024-11-03T13:17:09 '  File "quest.py", line 4807, in getQuestArea\n    raise Exception(f"{area_raw_name} current area isn\'t supported")\n'
2024-11-03T13:17:11 1_4_town current area isn't supported
2024-11-03T13:17:11 '  File "quest.py", line 4817, in <module>\n    current_quest_area = getQuestArea(poe_bot.game_data.area_raw_name)\n'
2024-11-03T13:17:11 '  File "quest.py", line 4807, in getQuestArea\n    raise Exception(f"{area_raw_name} current area isn\'t supported")\n'
2024-11-03T13:17:13 1_4_town current area isn't supported
2024-11-03T13:17:13 '  File "quest.py", line 4817, in <module>\n    current_quest_area = getQuestArea(poe_bot.game_data.area_raw_name)\n'
2024-11-03T13:17:13 '  File "quest.py", line 4807, in getQuestArea\n    raise Exception(f"{area_raw_name} current area isn\'t supported")\n'
2024-11-03T13:17:15 1_4_town current area isn't supported
2024-11-03T13:17:15 '  File "quest.py", line 4817, in <module>\n    current_quest_area = getQuestArea(poe_bot.game_data.area_raw_name)\n'
2024-11-03T13:17:15 '  File "quest.py", line 4807, in getQuestArea\n    raise Exception(f"{area_raw_name} current area isn\'t supported")\n'
2024-11-03T13:17:17 1_4_town current area isn't supported
2024-11-03T13:17:17 '  File "quest.py", line 4817, in <module>\n    current_quest_area = getQuestArea(poe_bot.game_data.area_raw_name)\n'
2024-11-03T13:17:17 '  File "quest.py", line 4807, in getQuestArea\n    raise Exception(f"{area_raw_name} current area isn\'t supported")\n'
2024-11-03T13:17:18 1_4_town current area isn't supported
2024-11-03T13:17:18 '  File "quest.py", line 4817, in <module>\n    current_quest_area = getQuestArea(poe_bot.game_data.area_raw_name)\n'
2024-11-03T13:17:18 '  File "quest.py", line 4807, in getQuestArea\n    raise Exception(f"{area_raw_name} current area isn\'t supported")\n'
2024-11-03T13:17:20 1_4_town current area isn't supported
2024-11-03T13:17:20 '  File "quest.py", line 4817, in <module>\n    current_quest_area = getQuestArea(poe_bot.game_data.area_raw_name)\n'
2024-11-03T13:17:20 '  File "quest.py", line 4807, in getQuestArea\n    raise Exception(f"{area_raw_name} current area isn\'t supported")\n'
2024-11-03T13:17:22 1_4_town current area isn't supported
2024-11-03T13:17:22 '  File "quest.py", line 4817, in <module>\n    current_quest_area = getQuestArea(poe_bot.game_data.area_raw_name)\n'
2024-11-03T13:17:22 '  File "quest.py", line 4807, in getQuestArea\n    raise Exception(f"{area_raw_name} current area isn\'t supported")\n'
2024-11-03T13:17:24 1_4_town current area isn't supported
2024-11-03T13:17:24 '  File "quest.py", line 4817, in <module>\n    current_quest_area = getQuestArea(poe_bot.game_data.area_raw_name)\n'
2024-11-03T13:17:24 '  File "quest.py", line 4807, in getQuestArea\n    raise Exception(f"{area_raw_name} current area isn\'t supported")\n'
2024-11-03T13:17:25 1_4_town current area isn't supported
2024-11-03T13:17:25 '  File "quest.py", line 4817, in <module>\n    current_quest_area = getQuestArea(poe_bot.game_data.area_raw_name)\n'
2024-11-03T13:17:25 '  File "quest.py", line 4807, in getQuestArea\n    raise Exception(f"{area_raw_name} current area isn\'t supported")\n'
2024-11-03T13:17:28 1_4_town current area isn't supported
2024-11-03T13:17:28 '  File "quest.py", line 4817, in <module>\n    current_quest_area = getQuestArea(poe_bot.game_data.area_raw_name)\n'
2024-11-03T13:17:28 '  File "quest.py", line 4807, in getQuestArea\n    raise Exception(f"{area_raw_name} current area isn\'t supported")\n'
2024-11-03T13:17:30 1_4_town current area isn't supported
2024-11-03T13:17:30 '  File "quest.py", line 4817, in <module>\n    current_quest_area = getQuestArea(poe_bot.game_data.area_raw_name)\n'
2024-11-03T13:17:30 '  File "quest.py", line 4807, in getQuestArea\n    raise Exception(f"{area_raw_name} current area isn\'t supported")\n'
2024-11-03T13:17:32 1_4_town current area isn't supported
2024-11-03T13:17:32 '  File "quest.py", line 4817, in <module>\n    current_quest_area = getQuestArea(poe_bot.game_data.area_raw_name)\n'
2024-11-03T13:17:32 '  File "quest.py", line 4807, in getQuestArea\n    raise Exception(f"{area_raw_name} current area isn\'t supported")\n'
2024-11-03T13:17:33 1_4_town current area isn't supported
2024-11-03T13:17:33 '  File "quest.py", line 4817, in <module>\n    current_quest_area = getQuestArea(poe_bot.game_data.area_raw_name)\n'
2024-11-03T13:17:33 '  File "quest.py", line 4807, in getQuestArea\n    raise Exception(f"{area_raw_name} current area isn\'t supported")\n'
2024-11-03T13:17:35 1_4_town current area isn't supported
2024-11-03T13:17:35 '  File "quest.py", line 4817, in <module>\n    current_quest_area = getQuestArea(poe_bot.game_data.area_raw_name)\n'
2024-11-03T13:17:35 '  File "quest.py", line 4807, in getQuestArea\n    raise Exception(f"{area_raw_name} current area isn\'t supported")\n'
2024-11-03T13:17:37 1_4_town current area isn't supported
2024-11-03T13:17:37 '  File "quest.py", line 4817, in <module>\n    current_quest_area = getQuestArea(poe_bot.game_data.area_raw_name)\n'
2024-11-03T13:17:37 '  File "quest.py", line 4807, in getQuestArea\n    raise Exception(f"{area_raw_name} current area isn\'t supported")\n'
2024-11-03T13:17:39 1_4_town current area isn't supported
2024-11-03T13:17:39 '  File "quest.py", line 4817, in <module>\n    current_quest_area = getQuestArea(poe_bot.game_data.area_raw_name)\n'
2024-11-03T13:17:39 '  File "quest.py", line 4807, in getQuestArea\n    raise Exception(f"{area_raw_name} current area isn\'t supported")\n'
2024-11-03T13:17:40 1_4_town current area isn't supported
2024-11-03T13:17:40 '  File "quest.py", line 4817, in <module>\n    current_quest_area = getQuestArea(poe_bot.game_data.area_raw_name)\n'
2024-11-03T13:17:40 '  File "quest.py", line 4807, in getQuestArea\n    raise Exception(f"{area_raw_name} current area isn\'t supported")\n'
2024-11-03T13:17:42 1_4_town current area isn't supported
2024-11-03T13:17:42 '  File "quest.py", line 4817, in <module>\n    current_quest_area = getQuestArea(poe_bot.game_data.area_raw_name)\n'
2024-11-03T13:17:42 '  File "quest.py", line 4807, in getQuestArea\n    raise Exception(f"{area_raw_name} current area isn\'t supported")\n'
2024-11-03T13:17:44 1_4_town current area isn't supported
2024-11-03T13:17:44 '  File "quest.py", line 4817, in <module>\n    current_quest_area = getQuestArea(poe_bot.game_data.area_raw_name)\n'
2024-11-03T13:17:44 '  File "quest.py", line 4807, in getQuestArea\n    raise Exception(f"{area_raw_name} current area isn\'t supported")\n'
2024-11-03T13:17:46 1_4_town current area isn't supported
2024-11-03T13:17:46 '  File "quest.py", line 4817, in <module>\n    current_quest_area = getQuestArea(poe_bot.game_data.area_raw_name)\n'
2024-11-03T13:17:46 '  File "quest.py", line 4807, in getQuestArea\n    raise Exception(f"{area_raw_name} current area isn\'t supported")\n'
2024-11-03T13:17:48 1_4_town current area isn't supported
2024-11-03T13:17:48 '  File "quest.py", line 4817, in <module>\n    current_quest_area = getQuestArea(poe_bot.game_data.area_raw_name)\n'
2024-11-03T13:17:48 '  File "quest.py", line 4807, in getQuestArea\n    raise Exception(f"{area_raw_name} current area isn\'t supported")\n'
2024-11-03T13:17:50 1_4_town current area isn't supported
2024-11-03T13:17:50 '  File "quest.py", line 4817, in <module>\n    current_quest_area = getQuestArea(poe_bot.game_data.area_raw_name)\n'
2024-11-03T13:17:50 '  File "quest.py", line 4807, in getQuestArea\n    raise Exception(f"{area_raw_name} current area isn\'t supported")\n'
2024-11-03T13:17:52 1_4_town current area isn't supported
2024-11-03T13:17:52 '  File "quest.py", line 4817, in <module>\n    current_quest_area = getQuestArea(poe_bot.game_data.area_raw_name)\n'
2024-11-03T13:17:52 '  File "quest.py", line 4807, in getQuestArea\n    raise Exception(f"{area_raw_name} current area isn\'t supported")\n'
2024-11-03T13:17:53 1_4_town current area isn't supported
2024-11-03T13:17:53 '  File "quest.py", line 4817, in <module>\n    current_quest_area = getQuestArea(poe_bot.game_data.area_raw_name)\n'
2024-11-03T13:17:53 '  File "quest.py", line 4807, in getQuestArea\n    raise Exception(f"{area_raw_name} current area isn\'t supported")\n'
2024-11-03T13:17:55 1_4_town current area isn't supported
2024-11-03T13:17:55 '  File "quest.py", line 4817, in <module>\n    current_quest_area = getQuestArea(poe_bot.game_data.area_raw_name)\n'
2024-11-03T13:17:55 '  File "quest.py", line 4807, in getQuestArea\n    raise Exception(f"{area_raw_name} current area isn\'t supported")\n'
2024-11-03T13:17:57 1_4_town current area isn't supported
2024-11-03T13:17:57 '  File "quest.py", line 4817, in <module>\n    current_quest_area = getQuestArea(poe_bot.game_data.area_raw_name)\n'
2024-11-03T13:17:57 '  File "quest.py", line 4807, in getQuestArea\n    raise Exception(f"{area_raw_name} current area isn\'t supported")\n'
2024-11-03T13:17:59 1_4_town current area isn't supported
2024-11-03T13:17:59 '  File "quest.py", line 4817, in <module>\n    current_quest_area = getQuestArea(poe_bot.game_data.area_raw_name)\n'
2024-11-03T13:17:59 '  File "quest.py", line 4807, in getQuestArea\n    raise Exception(f"{area_raw_name} current area isn\'t supported")\n'
2024-11-03T13:18:01 1_4_town current area isn't supported
2024-11-03T13:18:01 '  File "quest.py", line 4817, in <module>\n    current_quest_area = getQuestArea(poe_bot.game_data.area_raw_name)\n'
2024-11-03T13:18:01 '  File "quest.py", line 4807, in getQuestArea\n    raise Exception(f"{area_raw_name} current area isn\'t supported")\n'
2024-11-03T13:18:02 1_4_town current area isn't supported
2024-11-03T13:18:02 '  File "quest.py", line 4817, in <module>\n    current_quest_area = getQuestArea(poe_bot.game_data.area_raw_name)\n'
2024-11-03T13:18:02 '  File "quest.py", line 4807, in getQuestArea\n    raise Exception(f"{area_raw_name} current area isn\'t supported")\n'
2024-11-03T13:19:58 couldnt check the key
2024-11-03T13:19:58 '  File "quest.py", line 775, in <module>\n    poe_bot = PoeBot(unique_id=UNIQUE_ID, remote_ip = REMOTE_IP, debug = notebook_dev)\n'
2024-11-03T13:19:58 '  File "D:\\poe_bot\\1_host\\utils\\gamehelper.py", line 94, in __init__\n    self.checkIfReady()\n'
2024-11-03T13:19:58 '  File "D:\\poe_bot\\1_host\\utils\\gamehelper.py", line 132, in checkIfReady\n    raise Exception(\'couldnt check the key\')\n'
2024-11-03T13:25:21 exceptions must derive from BaseException
2024-11-03T13:25:21 '  File "quest.py", line 4818, in <module>\n    current_quest_area.complete()\n'
2024-11-03T13:25:21 '  File "quest.py", line 1225, in complete\n    raise "completed"\n'
2024-11-03T13:36:43 exceptions must derive from BaseException
2024-11-03T13:36:43 '  File "quest.py", line 4818, in <module>\n    current_quest_area.complete()\n'
2024-11-03T13:36:43 '  File "quest.py", line 1225, in complete\n    raise "completed"\n'
2024-11-03T16:47:59 i_count == 12: on sendCommand
2024-11-03T16:47:59 '  File "quest.py", line 4818, in <module>\n    current_quest_area.complete()\n'
2024-11-03T16:47:59 '  File "quest.py", line 1130, in complete\n    res = poe_bot.mover.goToPoint(\n'
2024-11-03T16:47:59 '  File "D:\\poe_bot\\1_host\\utils\\mover.py", line 505, in goToPoint\n    if bot_controls.mouse_pressed[\'left\'] is True and custom_continue_function(self) is True:\n'
2024-11-03T16:47:59 '  File "quest.py", line 523, in usualRoutine\n    if self.useSkillAsAttackingSkill(self.srs, nearby_enemies=nearby_enemies, really_close_enemies=really_close_enemies) == True:\n'
2024-11-03T16:47:59 '  File "quest.py", line 500, in useSkillAsAttackingSkill\n    if skill.use(updated_entity=enemy_to_attack) is True:\n'
2024-11-03T16:47:59 '  File "D:\\poe_bot\\1_host\\utils\\combat.py", line 608, in use\n    return super().use(pos_x, pos_y, updated_entity, wait_for_execution, False)\n'
2024-11-03T16:47:59 '  File "D:\\poe_bot\\1_host\\utils\\combat.py", line 539, in use\n    self.release(wait_till_executed = wait_for_execution)\n'
2024-11-03T16:47:59 '  File "D:\\poe_bot\\1_host\\utils\\combat.py", line 502, in release\n    self.release_func(button = self.skill_key)\n'
2024-11-03T16:47:59 '  File "D:\\poe_bot\\1_host\\utils\\controller.py", line 137, in keyboard_releaseKey\n    self.sendCommand(command=action_msg, wait_till_recieved=not wait_till_executed)\n'
2024-11-03T16:47:59 '  File "D:\\poe_bot\\1_host\\utils\\controller.py", line 63, in sendCommand\n    raise Exception(\'i_count == 12: on sendCommand\')\n'
2024-11-03T16:55:23 flask bug -2147483648 [0, 1730624117.494585, 1730624115.1717749, 1730624123.6514013, 1730624122.8702831]
2024-11-03T16:55:46 #resurrectAtCheckpoint call 1730624146.2978323
2024-11-03T16:56:09 #resurrectAtCheckpoint call 1730624169.0944622
2024-11-03T16:56:36 couldnt find next transition
2024-11-03T20:14:43 couldnt find next transition , sleep 3600*24
2024-11-03T20:14:43 '  File "quest.py", line 4817, in <module>\n    current_quest_area = getQuestArea(poe_bot.game_data.area_raw_name)\n'
2024-11-03T20:14:43 '  File "quest.py", line 4809, in getQuestArea\n    area_object = area_class()\n'
2024-11-03T20:14:43 '  File "quest.py", line 1440, in __init__\n    self.enterAfterResurrect()\n'
2024-11-03T20:14:43 '  File "quest.py", line 1414, in enterAfterResurrect\n    self.enterBossroomIfNeeded()\n'
2024-11-03T20:14:43 '  File "quest.py", line 1250, in enterBossroomIfNeeded\n    self.clearBossroom(bossroom_encounter)\n'
2024-11-03T20:14:43 '  File "quest.py", line 3330, in clearBossroom\n    bossroom_encounter.clearBossroom()\n'
2024-11-03T20:14:43 '  File "D:\\poe_bot\\1_host\\utils\\encounters.py", line 204, in clearBossroom\n    res = mover.goToPoint(\n'
2024-11-03T20:14:43 '  File "D:\\poe_bot\\1_host\\utils\\mover.py", line 501, in goToPoint\n    custom_break_function_result = custom_break_function(self)\n'
2024-11-03T20:14:43 '  File "D:\\poe_bot\\1_host\\utils\\encounters.py", line 186, in custom_break_function_nested\n    res = self.clear_room_custom_break_function(self.poe_bot.mover)\n'
2024-11-03T20:14:43 '  File "quest.py", line 3323, in lookForWardensChambers\n    poe_bot.raiseLongSleepException(\'couldnt find next transition\')\n'
2024-11-03T20:14:43 '  File "D:\\poe_bot\\1_host\\utils\\gamehelper.py", line 293, in raiseLongSleepException\n    raiseLongSleepException(text)\n'
2024-11-03T20:14:43 '  File "D:\\poe_bot\\1_host\\utils\\utils.py", line 43, in raiseLongSleepException\n    raise Exception(f\'{text} , sleep 3600*24\')\n'
2024-11-03T20:18:08 1_5_town current area isn't supported
2024-11-03T20:18:08 '  File "quest.py", line 4817, in <module>\n    current_quest_area = getQuestArea(poe_bot.game_data.area_raw_name)\n'
2024-11-03T20:18:08 '  File "quest.py", line 4807, in getQuestArea\n    raise Exception(f"{area_raw_name} current area isn\'t supported")\n'
2024-11-03T20:18:10 1_5_town current area isn't supported
2024-11-03T20:18:10 '  File "quest.py", line 4817, in <module>\n    current_quest_area = getQuestArea(poe_bot.game_data.area_raw_name)\n'
2024-11-03T20:18:10 '  File "quest.py", line 4807, in getQuestArea\n    raise Exception(f"{area_raw_name} current area isn\'t supported")\n'
2024-11-03T20:18:12 1_5_town current area isn't supported
2024-11-03T20:18:12 '  File "quest.py", line 4817, in <module>\n    current_quest_area = getQuestArea(poe_bot.game_data.area_raw_name)\n'
2024-11-03T20:18:12 '  File "quest.py", line 4807, in getQuestArea\n    raise Exception(f"{area_raw_name} current area isn\'t supported")\n'
2024-11-03T20:18:16 1_5_town current area isn't supported
2024-11-03T20:18:16 '  File "quest.py", line 4817, in <module>\n    current_quest_area = getQuestArea(poe_bot.game_data.area_raw_name)\n'
2024-11-03T20:18:16 '  File "quest.py", line 4807, in getQuestArea\n    raise Exception(f"{area_raw_name} current area isn\'t supported")\n'
2024-11-03T20:18:18 1_5_town current area isn't supported
2024-11-03T20:18:18 '  File "quest.py", line 4817, in <module>\n    current_quest_area = getQuestArea(poe_bot.game_data.area_raw_name)\n'
2024-11-03T20:18:18 '  File "quest.py", line 4807, in getQuestArea\n    raise Exception(f"{area_raw_name} current area isn\'t supported")\n'
2024-11-03T20:18:20 1_5_town current area isn't supported
2024-11-03T20:18:20 '  File "quest.py", line 4817, in <module>\n    current_quest_area = getQuestArea(poe_bot.game_data.area_raw_name)\n'
2024-11-03T20:18:20 '  File "quest.py", line 4807, in getQuestArea\n    raise Exception(f"{area_raw_name} current area isn\'t supported")\n'
2024-11-03T20:18:22 1_5_town current area isn't supported
2024-11-03T20:18:22 '  File "quest.py", line 4817, in <module>\n    current_quest_area = getQuestArea(poe_bot.game_data.area_raw_name)\n'
2024-11-03T20:18:22 '  File "quest.py", line 4807, in getQuestArea\n    raise Exception(f"{area_raw_name} current area isn\'t supported")\n'
2024-11-03T20:38:03 #resurrectAtCheckpoint call 1730637483.2028358
2024-11-03T20:38:54 #resurrectAtCheckpoint call 1730637534.6543543
2024-11-03T20:55:43 we are stuck hard, help!
2024-11-03T20:56:25 we are stuck hard, help! , sleep 3600*24
2024-11-03T20:56:25 '  File "quest.py", line 4818, in <module>\n    current_quest_area.complete()\n'
2024-11-03T20:56:25 '  File "quest.py", line 1130, in complete\n    res = poe_bot.mover.goToPoint(\n'
2024-11-03T20:56:25 '  File "D:\\poe_bot\\1_host\\utils\\mover.py", line 433, in goToPoint\n    poe_bot.raiseLongSleepException(\'we are stuck hard, help!\')\n'
2024-11-03T20:56:25 '  File "D:\\poe_bot\\1_host\\utils\\gamehelper.py", line 293, in raiseLongSleepException\n    raiseLongSleepException(text)\n'
2024-11-03T20:56:25 '  File "D:\\poe_bot\\1_host\\utils\\utils.py", line 43, in raiseLongSleepException\n    raise Exception(f\'{text} , sleep 3600*24\')\n'
2024-11-03T22:16:48 we are stuck hard, help!
2024-11-03T22:24:45 we are stuck hard, help! , sleep 3600*24
2024-11-03T22:24:45 '  File "quest.py", line 4818, in <module>\n    current_quest_area.complete()\n'
2024-11-03T22:24:45 '  File "quest.py", line 1130, in complete\n    res = poe_bot.mover.goToPoint(\n'
2024-11-03T22:24:45 '  File "D:\\poe_bot\\1_host\\utils\\mover.py", line 433, in goToPoint\n    poe_bot.raiseLongSleepException(\'we are stuck hard, help!\')\n'
2024-11-03T22:24:45 '  File "D:\\poe_bot\\1_host\\utils\\gamehelper.py", line 293, in raiseLongSleepException\n    raiseLongSleepException(text)\n'
2024-11-03T22:24:45 '  File "D:\\poe_bot\\1_host\\utils\\utils.py", line 43, in raiseLongSleepException\n    raise Exception(f\'{text} , sleep 3600*24\')\n'
2024-11-03T22:29:01 exceptions must derive from BaseException
2024-11-03T22:29:01 '  File "quest.py", line 4818, in <module>\n    current_quest_area.complete()\n'
2024-11-03T22:29:01 '  File "quest.py", line 1225, in complete\n    raise "completed"\n'
2024-11-03T23:05:00 we are stuck hard, help!
2024-11-03T23:05:01 we are stuck hard, help! , sleep 3600*24
2024-11-03T23:05:01 '  File "quest.py", line 4818, in <module>\n    current_quest_area.complete()\n'
2024-11-03T23:05:01 '  File "quest.py", line 1130, in complete\n    res = poe_bot.mover.goToPoint(\n'
2024-11-03T23:05:01 '  File "D:\\poe_bot\\1_host\\utils\\mover.py", line 501, in goToPoint\n    custom_break_function_result = custom_break_function(self)\n'
2024-11-03T23:05:01 '  File "quest.py", line 1091, in exploreRoutine\n    bossroom_encounter.leaveBossroom()\n'
2024-11-03T23:05:01 '  File "D:\\poe_bot\\1_host\\utils\\encounters.py", line 274, in leaveBossroom\n    while True:\n'
2024-11-03T23:05:01 '  File "D:\\poe_bot\\1_host\\utils\\mover.py", line 433, in goToPoint\n    poe_bot.raiseLongSleepException(\'we are stuck hard, help!\')\n'
2024-11-03T23:05:01 '  File "D:\\poe_bot\\1_host\\utils\\gamehelper.py", line 293, in raiseLongSleepException\n    raiseLongSleepException(text)\n'
2024-11-03T23:05:01 '  File "D:\\poe_bot\\1_host\\utils\\utils.py", line 43, in raiseLongSleepException\n    raise Exception(f\'{text} , sleep 3600*24\')\n'
2024-11-03T23:05:05 list index out of range
2024-11-03T23:05:05 '  File "quest.py", line 785, in <module>\n    poe_bot.game_data.terrain.getCurrentlyPassableArea()\n'
2024-11-03T23:05:05 '  File "D:\\poe_bot\\1_host\\utils\\gamehelper.py", line 462, in getCurrentlyPassableArea\n    nearest_passable_player_point = list(list(zip(nearest_passable_player_points[0], nearest_passable_player_points[1]))[0])\n'
2024-11-03T23:07:57 #resurrectAtCheckpoint call 1730646477.3469317
2024-11-03T23:09:02 #resurrectAtCheckpoint call 1730646542.1397686
2024-11-03T23:27:22 #resurrectAtCheckpoint call 1730647642.363103
2024-11-03T23:27:38 #resurrectAtCheckpoint call 1730647658.9406319
2024-11-03T23:28:05 #resurrectAtCheckpoint call 1730647685.24678
2024-11-03T23:28:35 #resurrectAtCheckpoint call 1730647715.0441058
2024-11-03T23:28:54 #resurrectAtCheckpoint call 1730647734.3978188
2024-11-03T23:29:08 #resurrectAtCheckpoint call 1730647748.5045505
