2024-10-03T22:02:49 i_count == 12: on sendCommand
2024-10-03T22:02:49 i_count == 12: on sendCommand
2024-10-03T22:02:49 '  File "quest.py", line 4629, in <module>\n    current_quest_area.complete()\n'
2024-10-03T22:02:49 '  File "quest.py", line 1083, in complete\n    res = poe_bot.mover.goToPoint(\n'
2024-10-03T22:02:49 '  File "C:\\poe_bot\\1_host\\utils\\mover.py", line 483, in goToPoint\n    self.move(screen_pos_x=int(pos_to_click[0]), screen_pos_y=int(pos_to_click[1]))\n'
2024-10-03T22:02:49 '  File "C:\\poe_bot\\1_host\\utils\\mover.py", line 600, in move\n    bot_controls.mousePress(pos_x,pos_y)\n'
2024-10-03T22:02:49 '  File "C:\\poe_bot\\1_host\\utils\\controller.py", line 86, in mousePress\n    self.sendCommand(command=action_msg, wait_till_recieved=not wait_till_executed)\n'
2024-10-03T22:02:49 '  File "C:\\poe_bot\\1_host\\utils\\controller.py", line 50, in sendCommand\n    raise Exception(\'i_count == 12: on sendCommand\')\n'
2024-10-03T22:08:00 #resurrectAtCheckpoint call 1727964480.270371
2024-10-03T22:08:14 i_count == 12: on sendCommand
2024-10-03T22:08:14 i_count == 12: on sendCommand
2024-10-03T22:08:14 '  File "quest.py", line 4629, in <module>\n    current_quest_area.complete()\n'
2024-10-03T22:08:14 '  File "quest.py", line 1083, in complete\n    res = poe_bot.mover.goToPoint(\n'
2024-10-03T22:08:14 '  File "C:\\poe_bot\\1_host\\utils\\mover.py", line 483, in goToPoint\n    self.move(screen_pos_x=int(pos_to_click[0]), screen_pos_y=int(pos_to_click[1]))\n'
2024-10-03T22:08:14 '  File "C:\\poe_bot\\1_host\\utils\\mover.py", line 602, in move\n    bot_controls.mouse.setPosSmooth(pos_x,pos_y, wait_till_executed=False)\n'
2024-10-03T22:08:14 '  File "C:\\poe_bot\\1_host\\utils\\controller.py", line 235, in setPosSmooth\n    self.controller.mouseSetCursorPosSmooth(x,y,wait_till_executed=wait_till_executed)\n'
2024-10-03T22:08:14 '  File "C:\\poe_bot\\1_host\\utils\\controller.py", line 74, in mouseSetCursorPosSmooth\n    self.sendCommand(command=action_msg, wait_till_recieved=not wait_till_executed)\n'
2024-10-03T22:08:14 '  File "C:\\poe_bot\\1_host\\utils\\controller.py", line 50, in sendCommand\n    raise Exception(\'i_count == 12: on sendCommand\')\n'
2024-10-03T22:12:46 couldnt check the key
2024-10-03T22:12:46 couldnt check the key
2024-10-03T22:12:46 '  File "quest.py", line 727, in <module>\n    poe_bot = PoeBot(unique_id=UNIQUE_ID, remote_ip = REMOTE_IP, debug = notebook_dev)\n'
2024-10-03T22:12:46 '  File "C:\\poe_bot\\1_host\\utils\\gamehelper.py", line 101, in __init__\n    self.checkIfReady()\n'
2024-10-03T22:12:46 '  File "C:\\poe_bot\\1_host\\utils\\gamehelper.py", line 142, in checkIfReady\n    raise Exception(\'couldnt check the key\')\n'
2024-10-03T22:19:20 exceptions must derive from BaseException
2024-10-03T22:19:20 exceptions must derive from BaseException
2024-10-03T22:19:20 '  File "quest.py", line 4629, in <module>\n    current_quest_area.complete()\n'
2024-10-03T22:19:20 '  File "quest.py", line 1178, in complete\n    raise "completed"\n'
2024-10-03T22:20:49 #resurrectAtCheckpoint call 1727965249.1564047
2024-10-03T22:21:24 #resurrectAtCheckpoint call 1727965284.644277
2024-10-03T22:21:48 #resurrectAtCheckpoint call 1727965308.4304795
2024-10-03T22:22:02 #resurrectAtCheckpoint call 1727965322.508221
2024-10-03T23:31:32 couldnt connect to 172.21.164.37, maybe start.bat on guest isnt launched? or ip is wrong
2024-10-03T23:31:32 couldnt connect to 172.21.164.37, maybe start.bat on guest isnt launched? or ip is wrong
2024-10-03T23:31:32 '  File "quest.py", line 4628, in <module>\n    current_quest_area = getQuestArea(poe_bot.game_data.area_raw_name)\n'
2024-10-03T23:31:32 '  File "quest.py", line 4620, in getQuestArea\n    area_object = area_class()\n'
2024-10-03T23:31:32 '  File "quest.py", line 3760, in __init__\n    super().__init__()\n'
2024-10-03T23:31:32 '  File "quest.py", line 1384, in __init__\n    self.enterAfterResurrect()\n'
2024-10-03T23:31:32 '  File "quest.py", line 1367, in enterAfterResurrect\n    self.enterBossroomIfNeeded()\n'
2024-10-03T23:31:32 '  File "quest.py", line 1203, in enterBossroomIfNeeded\n    self.clearBossroom(bossroom_encounter)\n'
2024-10-03T23:31:32 '  File "quest.py", line 3774, in clearBossroom\n    bossroom_encounter.clearBossroom()\n'
2024-10-03T23:31:32 '  File "C:\\poe_bot\\1_host\\utils\\encounters.py", line 204, in clearBossroom\n    res = mover.goToPoint(\n'
2024-10-03T23:31:32 '  File "C:\\poe_bot\\1_host\\utils\\mover.py", line 385, in goToPoint\n    poe_bot.raiseLongSleepException(\'we are stuck hard, help!\')\n'
2024-10-03T23:31:32 '  File "C:\\poe_bot\\1_host\\utils\\gamehelper.py", line 348, in raiseLongSleepException\n    bot_controls.restartScript()\n'
2024-10-03T23:31:32 '  File "C:\\poe_bot\\1_host\\utils\\controller.py", line 118, in restartScript\n    self.connect()\n'
2024-10-03T23:31:32 '  File "C:\\poe_bot\\1_host\\utils\\controller.py", line 42, in connect\n    raise Exception(text)\n'
2024-10-03T23:34:42 exceptions must derive from BaseException
2024-10-03T23:34:42 exceptions must derive from BaseException
2024-10-03T23:34:42 '  File "quest.py", line 4629, in <module>\n    current_quest_area.complete()\n'
2024-10-03T23:34:42 '  File "quest.py", line 1178, in complete\n    raise "completed"\n'
2024-10-03T23:37:19 #resurrectAtCheckpoint call 1727969839.475051
2024-10-03T23:37:47 #resurrectAtCheckpoint call 1727969867.286012
2024-10-03T23:39:11 exceptions must derive from BaseException
2024-10-03T23:39:11 exceptions must derive from BaseException
2024-10-03T23:39:11 '  File "quest.py", line 4629, in <module>\n    current_quest_area.complete()\n'
2024-10-03T23:39:11 '  File "quest.py", line 1178, in complete\n    raise "completed"\n'
2024-10-03T23:39:17 relogging through char select screen
2024-10-03T23:39:18 getting to char selection screen from game
2024-10-03T23:45:13 couldnt check the key
2024-10-03T23:45:13 couldnt check the key
2024-10-03T23:45:13 '  File "quest.py", line 727, in <module>\n    poe_bot = PoeBot(unique_id=UNIQUE_ID, remote_ip = REMOTE_IP, debug = notebook_dev)\n'
2024-10-03T23:45:13 '  File "C:\\poe_bot\\1_host\\utils\\gamehelper.py", line 101, in __init__\n    self.checkIfReady()\n'
2024-10-03T23:45:13 '  File "C:\\poe_bot\\1_host\\utils\\gamehelper.py", line 142, in checkIfReady\n    raise Exception(\'couldnt check the key\')\n'
2024-10-03T23:45:17 couldnt connect to 172.21.164.37, maybe start.bat on guest isnt launched? or ip is wrong
2024-10-03T23:45:17 couldnt connect to 172.21.164.37, maybe start.bat on guest isnt launched? or ip is wrong
2024-10-03T23:45:17 '  File "quest.py", line 736, in <module>\n    bot_controls.restartScript()\n'
2024-10-03T23:45:17 '  File "C:\\poe_bot\\1_host\\utils\\controller.py", line 118, in restartScript\n    self.connect()\n'
2024-10-03T23:45:17 '  File "C:\\poe_bot\\1_host\\utils\\controller.py", line 42, in connect\n    raise Exception(text)\n'
2024-10-03T23:57:28 list index out of range
2024-10-03T23:57:28 list index out of range
2024-10-03T23:57:28 '  File "quest.py", line 738, in <module>\n    poe_bot.game_data.terrain.getCurrentlyPassableArea()\n'
2024-10-03T23:57:28 '  File "C:\\poe_bot\\1_host\\utils\\gamehelper.py", line 504, in getCurrentlyPassableArea\n    nearest_passable_player_point = list(list(zip(nearest_passable_player_points[0], nearest_passable_player_points[1]))[0])\n'
2024-10-03T23:58:33 #resurrectAtCheckpoint call 1727971113.643074
2024-10-03T23:59:05 #resurrectAtCheckpoint call 1727971145.6546614
2024-10-03T23:59:28 #resurrectAtCheckpoint call 1727971168.7714887
